<?xml version="1.0" encoding="utf-8"?>

<robot name="robot_description">
<!-- %%%%%%%%%%%%%%%%%%%%%%%%%%%% LINKS %%%%%%%%%%%%%%%%%%%%%%%%%%%% -->
  <!-- %%%%%%%%%%%%%%%%%%%%%%% BASE LINK %%%%%%%%%%%%%%%%%%%%%%% -->
    <link name="base_link">
      <inertial>
        <origin
          xyz="-1.5853E-16 5.2101E-17 -0.015636"
          rpy="0 0 0" />
        <mass
          value="0.36521" />
        <inertia
          ixx="0.00039748"
          ixy="-4.0792E-09"
          ixz="7.1512E-18"
          iyy="0.00072454"
          iyz="-1.3047E-18"
          izz="0.0010802" />
      </inertial>
      <visual>
        <origin
          xyz="0 0 0"
          rpy="0 0 0" />
        <geometry>
          <mesh
            filename="package://robot_description/meshes/base_link.STL" />
        </geometry>
        <material
          name="">
          <color
            rgba="0.75294 0.75294 0.75294 1" />
        </material>
      </visual>
      <collision>
        <origin
          xyz="0 0 0"
          rpy="0 0 0" />
        <geometry>
          <mesh
            filename="package://robot_description/meshes/base_link.STL" />
        </geometry>
      </collision>
    </link>
  <!-- %%%%%%%%%%%%%%%%%%%%% FR WHEEL LINK %%%%%%%%%%%%%%%%%%%%% -->
    <link name="fr_wheel_link">
      <inertial>
        <origin
          xyz="1.8041E-16 -0.011571 5.9328E-16"
          rpy="0 0 0" />
        <mass
          value="0.041912" />
        <inertia
          ixx="3.6789E-06"
          ixy="7.9409E-23"
          ixz="-2.3641E-21"
          iyy="3.5671E-06"
          iyz="8.8839E-22"
          izz="3.6789E-06" />
      </inertial>
      <visual>
        <origin
          xyz="0 0 0"
          rpy="0 0 0" />
        <geometry>
          <mesh
            filename="package://robot_description/meshes/fr_wheel_link.STL" />
        </geometry>
        <material
          name="">
          <color
            rgba="0.75294 0.75294 0.75294 1" />
        </material>
      </visual>
      <collision>
        <origin
          xyz="0 0 0"
          rpy="0 0 0" />
        <geometry>
          <mesh
            filename="package://robot_description/meshes/fr_wheel_link.STL" />
        </geometry>
      </collision>   
    </link>
  <!-- %%%%%%%%%%%%%%%%%%%%% FL WHEEL LINK %%%%%%%%%%%%%%%%%%%%% -->
    <link name="fl_wheel_link">
      <inertial>
        <origin
          xyz="5.4956E-15 0.011595 -7.8063E-16"
          rpy="0 0 0" />
        <mass
          value="0.041912" />
        <inertia
          ixx="3.6789E-06"
          ixy="-1.1316E-21"
          ixz="9.3084E-21"
          iyy="3.5669E-06"
          iyz="-6.9925E-22"
          izz="3.6789E-06" />
      </inertial>
      <visual>
        <origin
          xyz="0 0 0"
          rpy="0 0 0" />
        <geometry>
          <mesh
            filename="package://robot_description/meshes/fl_wheel_link.STL" />
        </geometry>
        <material
          name="">
          <color
            rgba="0.75294 0.75294 0.75294 1" />
        </material>
      </visual>
      <collision>
        <origin
          xyz="0 0 0"
          rpy="0 0 0" />
        <geometry>
          <mesh
            filename="package://robot_description/meshes/fl_wheel_link.STL" />
        </geometry>
      </collision>
    </link>
  <!-- %%%%%%%%%%%%%%%%%%%%% BR WHEEL LINK %%%%%%%%%%%%%%%%%%%%% -->
    <link name="br_wheel_link">
      <inertial>
        <origin
          xyz="5.7454E-15 -0.011499 -2.8103E-16"
          rpy="0 0 0" />
        <mass
          value="0.041912" />
        <inertia
          ixx="3.6789E-06"
          ixy="-5.9722E-22"
          ixz="9.4729E-21"
          iyy="3.5669E-06"
          iyz="-2.4485E-22"
          izz="3.6789E-06" />
      </inertial>
      <visual>
        <origin
          xyz="0 0 0"
          rpy="0 0 0" />
        <geometry>
          <mesh
            filename="package://robot_description/meshes/br_wheel_link.STL" />
        </geometry>
        <material
          name="">
          <color
            rgba="0.75294 0.75294 0.75294 1" />
        </material>
      </visual>
      <collision>
        <origin
          xyz="0 0 0"
          rpy="0 0 0" />
        <geometry>
          <mesh
            filename="package://robot_description/meshes/br_wheel_link.STL" />
        </geometry>
      </collision>
    </link>
  <!-- %%%%%%%%%%%%%%%%%%%%% BL WHEEL LINK %%%%%%%%%%%%%%%%%%%%% -->
    <link name="bl_wheel_link">
      <inertial>
        <origin
          xyz="1.1102E-16 0.011429 -1.6653E-16"
          rpy="0 0 0" />
        <mass
          value="0.041912" />
        <inertia
          ixx="3.6789E-06"
          ixy="-1.5032E-22"
          ixz="-2.9973E-21"
          iyy="3.5671E-06"
          iyz="1.1701E-21"
          izz="3.6789E-06" />
      </inertial>
      <visual>
        <origin
          xyz="0 0 0"
          rpy="0 0 0" />
        <geometry>
          <mesh
            filename="package://robot_description/meshes/bl_wheel_link.STL" />
        </geometry>
        <material
          name="">
          <color
            rgba="0.75294 0.75294 0.75294 1" />
        </material>
      </visual>
      <collision>
        <origin
          xyz="0 0 0"
          rpy="0 0 0" />
        <geometry>
          <mesh
            filename="package://robot_description/meshes/bl_wheel_link.STL" />
        </geometry>
      </collision>
    </link>

<!-- %%%%%%%%%%%%%%%%%%%%%%%%%%%% JOINTS %%%%%%%%%%%%%%%%%%%%%%%%%%%% -->
  <!-- %%%%%%%%%%%%%%%%%%%% FR WHEEL JOINT %%%%%%%%%%%%%%%%%%%% -->
    <joint name="fr_wheel_joint"
      type="continuous">
      <origin
        xyz="0.10615 -0.085325 -0.0303"
        rpy="0 0 0" />
      <parent
        link="base_link" />
      <child
        link="fr_wheel_link" />
      <axis
        xyz="0 -1 0" />
    </joint>
  <!-- %%%%%%%%%%%%%%%%%%%%% FL WHEEL JOINT %%%%%%%%%%%%%%%%%%%%% -->
    <joint name="fl_wheel_joint"
      type="continuous">
      <origin
        xyz="0.10615 0.085325 -0.0303"
        rpy="0 0 0" />
      <parent
        link="base_link" />
      <child
        link="fl_wheel_link" />
      <axis
        xyz="0 1 0" />
    </joint>
  <!-- %%%%%%%%%%%%%%%%%%%%% BR WHEEL JOINT %%%%%%%%%%%%%%%%%%%%% -->
    <joint name="br_wheel_joint"
      type="continuous">
      <origin
        xyz="-0.10615 -0.085325 -0.0303"
        rpy="0 0 0" />
      <parent
        link="base_link" />
      <child
        link="br_wheel_link" />
      <axis
        xyz="0 -1 0" />
    </joint>
  <!-- %%%%%%%%%%%%%%%%%%%%% BR WHEEL JOINT %%%%%%%%%%%%%%%%%%%%% -->
    <joint name="bl_wheel_joint"
      type="continuous">
      <origin
        xyz="-0.10615 0.085325 -0.0303"
        rpy="0 0 0" />
      <parent
        link="base_link" />
      <child
        link="bl_wheel_link" />
      <axis
        xyz="0 1 0" />
    </joint>

  <!-- ros_control plugin -->
    <gazebo>
      <plugin name="zm_robot_diff_drive" filename="libgazebo_ros_mecanum_drive.so">
        <commandTopic>cmd_vel</commandTopic>
        <odometryTopic>odom</odometryTopic>
        <odometryFrame>odom</odometryFrame>
        <robotBaseFrame>base_footprint</robotBaseFrame>
        <LeftRear>bl_wheel_link</LeftRear>
        <LeftFront>fl_wheel_link</LeftFront>
        <RightFront>fr_wheel_link</RightFront>
        <RightRear>br_wheel_link</RightRear>
        <odometryRate>50</odometryRate>      
        <publishWheelTF>false</publishWheelTF>
        <publishWheelJointState>true</publishWheelJointState>
        <WheelTorque>40</WheelTorque>
        <WheelSeparationW>0.5</WheelSeparationW>
        <WheelSeparationL>0.6</WheelSeparationL>
        <wheelAccel>50</wheelAccel>
        <wheelDiameter>0.13</wheelDiameter>
        <publishOdom>true</publishOdom>
        <isRollerModel>true</isRollerModel>
      </plugin>
   </gazebo>

</robot>